## 동기 상황에서의 에러 핸들링

```c
function f(list) {
  return list
    .map(a => a + 10)
    .filter(a => a % 2)
    .slice(0, 2);
}

log(f([]));   // output []
log(f(null)); // output -> ERROR

// 방안 1 
function f(list) {
  return (list || [])
    .map(a => a + 10)
    .filter(a => a % 2)
    .slice(0, 2);
}

log(f([]));   // output []
log(f(null)); // output []

// 방안 2
function f(list) {
  try {
    return (list || [])
      .map(a => a + 10)
      .filter(a => a % 2)
      .slice(0, 2);
  } catch (e) {
    console.log("ERROR is : ", e);
    return [];
  }
}

log(f([]));   // output []
log(f(null)); // output []
```

## 비동기 상황에서의 에러 핸들링

두가지 방안 모두 비동기 상황에서 에러 핸들링이 되지 않는다. 

```c
// 이걸 에러 핸들링 잘하려면 Promise를 잘 다뤄야 한다. 

function f(list) {
  try {
    return (list || [])
      .map(a => new Promise(resolve => {
        resolve(JSON.parse(a));
      }))
      .filter(a => a % 2)
      .slice(0, 2);
  } catch (e) {
    console.log("ERROR is : ", e);
    return [];
  }
}

log(f(['1','2','3','4','{']));   // 빈배열 [] 출력 후 error 발생. <handling되지 못했다.>
```

```c
async function f(list) {
  try {
    return await (list || [])
      .map(async a => await new Promise(resolve => {
        resolve(JSON.parse(a));
      }))
      .filter(a => a % 2)
      .slice(0, 2);
  } catch (e) {
    console.log("ERROR is : ", e);
    return [];
  }
}

//log(f(['1','2','3','4','{']));   // 빈배열 [] 출력 후 error 발생. <handling되지 못했다.> 
f(['0','1','2','3','{']).then(log).catch(e => {log("ERROR Handling ")}); 
// Promise 내부에서 에러가 생겼으면 Promise 상태가 reject으로 변한다.
```

pipe형태로 구성하면 외부에서 catch된다. 

```c
// 이걸 에러 핸들링 잘하려면 Promise를 잘 다뤄야 한다. 
// 코드를 pipe형태로 만들면 에러핸들링이 된다. 
async function f(list) {
  try {
    return go(
      list,
      map(a => new Promise(resolve => {
        resolve(JSON.parse(a));
      })),
      filter(a => a % 2),
      take(2));
  } catch {
    log(e, '------');
    return [];
  }
}

f(['0','1','2','}']).then(log).catch(e => {
  log('error 핸들링');
}); // 이 catch로는 오지만 f안의 catch 로 가지 않는다.
```

- 내부 catch에 handling 되려면 try에서 return되는 값이 Promise.reject로 평가되어야 한다.

파이프 구조에서 await을 붙이면 

```c
async function f(list) {
  try {
    return await go( // await을 붙이지 않으면 catch로 정상적으로 가지 않는다.
      list,
      map(a => new Promise(resolve => {
        resolve(JSON.parse(a));
      })),
      filter(a => a % 2),
      take(2));
  } catch (e) {
    log("ERROR is : ", e, '------');
    return [];
  }
}

f(['0','1','2','}']).then(log);/*.catch(e => {
  log('error 핸들링');
});*/ // 이 catch로는 오지만 f안의 catch 로 가지 않는다.
```

핸들링이 정상적으로 된다. 

위와같은 방법으로 에러 핸들링을 하기 위해서는 Promise객체가 끝까지 전달되면서 상태가 tracking되어야 한다. 이러한 상태를 유지하는데 가장 유리한 방법이 파이프구조이다. 

### Lazy Evaluation 과 에러 핸들링

```c
async function f(list) {
  try {
    return await go( // await을 붙이지 않으면 catch로 정상적으로 가지 않는다.
      list,
      map(a => new Promise(resolve => {
        resolve(JSON.parse(a));
      })),
      filter(a => a % 2),
      take(2));
  } catch (e) {
    log("ERROR is : ", e, '------');
    return [];
  }
}

f(['0','1','2','3','4','}']).then(log); 
```

만약, map과 filter가 Lazy하게 평가된다고 하면, 위 코드는 에러가 발생하지 않는다. (2개만  take하면 되기 때문에 잘못된 입력인 '}' 까지 가지 않는다. 이 상황을 의도한 것이라면 Lazy Evaluation을 하고 아니라면 map만 즉시평가를 시켜 에러를 처리할 수 있다.
